<mujoco model="flamingo_edu_v1">
    <compiler angle="radian" />
    <option timestep="0.005" iterations="50" solver="Newton" jacobian="dense" integrator="implicitfast" />

    <visual>
        <headlight diffuse="1 1 1" ambient="0.3 0.3 0.3" specular="0 0 0" />
        <rgba haze="0.15 0.25 0.35 1" />
        <global azimuth="120" elevation="-20" />
    </visual>

    <default>
        <default class="visual">
            <geom contype="0" conaffinity="0" group="2" />
        </default>

        <default class="collision">
            <geom group="3" />
        </default>

        <default class="collision_mesh">
            <geom contype="1" conaffinity="1" group="0" />
        </default>

        <default class="joints">
            <joint damping="0.5" stiffness="0.0" frictionloss="0.1" armature="0.01" actuatorfrclimited="true" actuatorfrcrange="-12 12" />
        </default>
        <default class="wheels">
            <joint damping="0.0" stiffness="0.0" frictionloss="0.1" armature="0.01" actuatorfrclimited="true" actuatorfrcrange="-12 12" />
        </default>
    </default>

    <worldbody>
        <geom name="groundplane" pos="0 0 0" size="140 140 0.1" type="plane" material="MatPlane" friction="0.8 0.2 0.002" condim="3" solref="0.002 1" solimp="0.9 0.95 0.05" />
        <body name="base_link" pos="0.0 0.0 0.2607">
            <inertial pos="-0.00589457 0.00113829 -0.05282656" mass="2.681608094892505" diaginertia="0.01981432 0.00625385 0.01642957" />
            <geom type="mesh" mesh="base_link" rgba="0.2 0.2 0.2 1" class="visual" />
            <geom type="box" size="0.09 0.12 0.08" pos="-0.04 0 -0.08" rgba="0.8 0.2 0.2 0.3" class="collision" />
            <joint name="base_free_joint" type="free" damping="0.0" />
            <site name="imu" size="0.01" pos="0.021 0.00025 -0.042" />
            <body name="left_shoulder_link" pos="-0.004 0.136 -0.08" quat="-2.59734e-06 -2.59735e-06 -0.707108 -0.707105">
            <inertial pos="0.0231929 0.00232951 0.00696198" quat="-0.0335555 0.702863 0.0331623 0.709759" mass="0.15417845137327513" diaginertia="0.000398226 0.000381372 1.97217e-05" />
            <joint name="left_shoulder_joint" pos="0 0 0" axis="0 0 1" range="-1.2754 0" class="joints" />
            <geom type="mesh" rgba="0.1 0.1 0.1 1" mesh="left_shoulder_link" />
            <body name="left_leg_link" pos="0.15929 0.015078 0.00045">
                <inertial pos="-0.116331 -0.083206 0.00347048" quat="-0.21129 0.688661 0.22162 0.657257" mass="0.447" diaginertia="0.0016698 0.00154929 0.000189558" />
                <joint name="left_leg_joint" pos="0 0 0" axis="0 0 1" range="0 2.61799" class="joints" />
                <geom type="mesh" rgba="0.1 0.1 0.1 1" mesh="left_leg_link" />
                <body name="left_wheel_link" pos="-0.13 -0.093274 0.0315">
                <inertial pos="0.00004532 0.00006323 0.01284742" quat="0.5 0.5 -0.5 0.5" mass="0.5520413527107123" diaginertia="0.00138510 0.00138510 0.00267419" />
                <joint name="left_wheel_joint" pos="0 0 0" axis="0 0 1" type="hinge" limited="false" class="wheels" />
                <geom type="mesh" rgba="0.15 0.15 0.15 1" mesh="left_wheel_link" class="visual" />
                <geom type="cylinder" size="0.1025 0.0175" pos="0 0 0.02" rgba="0.8 0.2 0.2 0.3" class="collision" />
                </body>
            </body>
            </body>
            <body name="right_shoulder_link" pos="-0.004 -0.136 -0.08" quat="0.707105 0.707108 0 0">
            <inertial pos="-0.023218 0.00206382 0.00696198" quat="0.0331623 0.709759 -0.0335555 0.702863" mass="0.14505240369817798" diaginertia="0.000398226 0.000381372 1.97217e-05" />
            <joint name="right_shoulder_joint" pos="0 0 0" axis="0 0 -1" range="-1.2754 0" class="joints" />
            <geom type="mesh" rgba="0.1 0.1 0.1 1" mesh="right_shoulder_link" />
            <body name="right_leg_link" pos="-0.15929 0.015078 0.00045">
                <inertial pos="0.116087 -0.0835527 0.00347179" quat="0.221409 0.657201 -0.211466 0.688729" mass="0.447" diaginertia="0.0016698 0.00154929 0.000189561" />
                <joint name="right_leg_joint" pos="0 0 0" axis="0 0 -1" range="0 2.61799" class="joints" />
                <geom type="mesh" rgba="0.1 0.1 0.1 1" mesh="right_leg_link" />
                <body name="right_wheel_link" pos="0.13 -0.093274 0.0315">
                <inertial pos="0.00007441 -0.00002268 0.01284742" quat="0.5 0.5 -0.5 0.5" mass="0.5722492721450863" diaginertia="0.00138510 0.00138510 0.00267419" />
                <joint name="right_wheel_joint" pos="0 0 0" axis="0 0 -1" type="hinge" limited="false" class="wheels" />
                <geom type="mesh" rgba="0.15 0.15 0.15 1" mesh="right_wheel_link" class="visual" />
                <geom type="cylinder" size="0.1025 0.0175" pos="0 0 0.02" rgba="0.8 0.2 0.2 0.3" class="collision" />
                </body>
            </body>
            </body>
            <body name="left_upper_link" pos="-0.052209 0.143 -0.022547" quat="-2.59734e-06 -2.59735e-06 0.707108 0.707105">
            <inertial pos="0.0799144 -0.00369865 0" quat="0.0163446 0.706918 -0.0163446 0.706918" mass="0.04273" diaginertia="0.00010569 0.000105163 9.77457e-07" />
            <joint name="left_upper_joint" pos="0 0 0" axis="0 0 1" range="-1.74533 0" class="joints" />
            <geom type="mesh" rgba="0.1 0.1 0.1 1" mesh="left_upper_link" />
            </body>
            <body name="right_upper_link" pos="-0.052209 -0.144 -0.022547" quat="0.707105 0.707108 0 0">
            <inertial pos="-0.0799144 -0.00369865 0" quat="-0.0163446 0.706918 0.0163446 0.706918" mass="0.04273" diaginertia="0.00010569 0.000105163 9.77457e-07" />
            <joint name="right_upper_joint" pos="0 0 0" axis="0 0 -1" range="-1.74533 0" class="joints" />
            <geom type="mesh" rgba="0.1 0.1 0.1 1" mesh="right_upper_link" />
            </body>
            <body name="front_cover_link" pos="0.052 0 -0.078496" quat="1 0 0 0">
                <inertial pos="-0.01450628 -0.00000001 -0.00353267" mass="0.19400000" diaginertia="0.00111820 0.00041282 0.00074533" />
                <geom type="mesh" rgba="0.15 0.15 0.15 1" mesh="front_cover_link" class="visual" />
            </body>
            <body name="rear_cover_link" pos="-0.126 0 -0.0806008" quat="1 0 0 0">
                <inertial pos="0.04255973 -0.00349397 0.00235904" mass="0.49900000" diaginertia="0.00295846 0.00146584 0.00233337" />
                <geom type="mesh" rgba="0.15 0.15 0.15 1" mesh="rear_cover_link" class="visual" />
            </body>
        </body>
    </worldbody>

    <asset>
        <texture type="skybox" builtin="gradient" rgb1="0.3 0.5 0.7" rgb2="0 0 0" width="512" height="3072" />
        <texture type="2d" name="groundplane" builtin="checker" mark="edge" rgb1="0.2 0.3 0.4" rgb2="0.1 0.2 0.3" markrgb="0.8 0.8 0.8" width="300" height="300" />
        <material name="MatPlane" texture="groundplane" texuniform="true" texrepeat="5 5" reflectance="0.2" />
        <material name="rubber" rgba="0.4 0.4 0.4 1" shininess="0.5" reflectance="0.2" />

        <mesh name="base_link" file="../mesh/base_link.STL" />
        <mesh name="front_cover_link" file="../mesh/front_cover_link.STL" />
        <mesh name="rear_cover_link" file="../mesh/rear_cover_link.STL" />

        <mesh name="left_shoulder_link" file="../mesh/left_shoulder_link.STL" />
        <mesh name="left_leg_link" file="../mesh/left_leg_link.STL" />
        <mesh name="left_wheel_link" file="../mesh/left_wheel_link.STL" />

        <mesh name="right_shoulder_link" file="../mesh/right_shoulder_link.STL" />
        <mesh name="right_leg_link" file="../mesh/right_leg_link.STL" />
        <mesh name="right_wheel_link" file="../mesh/right_wheel_link.STL" />

        <mesh name="left_upper_link" file="../mesh/left_upper_link.STL" />
        <mesh name="right_upper_link" file="../mesh/right_upper_link.STL" />

        <hfield name="flat" file="../terrain/flat.png" nrow="64" ncol="64" size="140 140 10 0.1" />
        <hfield name="rocky_easy" file="../terrain/rocky_easy.png" nrow="512" ncol="512" size="140 140 0.1 0.1" />
        <hfield name="rocky_hard" file="../terrain/rocky_hard.png" nrow="512" ncol="512" size="140 140 0.25 0.1" />
        <hfield name="slope_easy" file="../terrain/slope_easy.png" nrow="512" ncol="512" size="140 140 0.5 0.1" />
        <hfield name="slope_hard" file="../terrain/slope_hard.png" nrow="512" ncol="512" size="140 140 1 0.1" />
        <hfield name="stairs_easy" file="../terrain/stairs_easy.png" nrow="128" ncol="8192" size="140 140 0.32 0.1" />
        <hfield name="stairs_hard" file="../terrain/stairs_hard.png" nrow="128" ncol="8192" size="140 140 0.64 0.1" />
    </asset>

	<equality>
		<connect body2="left_upper_link" body1="left_leg_link" anchor="0.0495 0.035 0.0075" solimp="0.001 1" />
		<connect body2="right_upper_link" body1="right_leg_link" anchor="-0.0495 0.035 0.0075" solimp="0.001 1" />
	</equality>

    <contact>
        <exclude name="exclude_left_uppler_link" body1="left_leg_link" body2="left_upper_link" />
        <exclude name="exclude_right_uppler_link" body1="right_leg_link" body2="right_upper_link" />
        <exclude name="exclude_left_wheel_link" body1="left_wheel_link" body2="left_leg_link" />
        <exclude name="exclude_right_wheel_link" body1="right_wheel_link" body2="right_leg_link" />
        <exclude name="exclude_left_shoulder_link" body1="left_shoulder_link" body2="left_leg_link" />
        <exclude name="exclude_right_shoulder_link" body1="right_shoulder_link" body2="right_leg_link" />
        <exclude name="exclude_base_link1" body1="base_link" body2="left_leg_link" />
        <exclude name="exclude_base_link2" body1="base_link" body2="right_leg_link" />
    </contact>

    <actuator>
        
        <motor joint="left_shoulder_joint" name="left_shoulder_motor" ctrllimited="true" ctrlrange="-12 12" />
        <motor joint="right_shoulder_joint" name="right_shoulder_motor" ctrllimited="true" ctrlrange="-12 12" />

        
        <motor joint="left_wheel_joint" name="left_wheel_motor" ctrllimited="true" ctrlrange="-12 12" />
        <motor joint="right_wheel_joint" name="right_wheel_motor" ctrllimited="true" ctrlrange="-12 12" />
    </actuator>

    <sensor>
        <framequat name="orientation" objtype="site" noise="0.1" objname="imu" />
        <framepos name="position" objtype="site" noise="0.1" objname="imu" />
        <gyro name="angular-velocity" site="imu" noise="0.2" cutoff="34.9" />
        <velocimeter name="linear-velocity" site="imu" noise="0.1" cutoff="30" />
        <accelerometer name="linear-acceleration" site="imu" noise="0.05" cutoff="157" />
        <magnetometer name="magnetometer" site="imu" />
    </sensor>
</mujoco>